{
 "cells": [
  {
   "cell_type": "markdown",
   "metadata": {},
   "source": [
    "# Software Development: Documentation and Errors"
   ]
  },
  {
   "cell_type": "markdown",
   "metadata": {},
   "source": [
    "## Type Hinting"
   ]
  },
  {
   "cell_type": "markdown",
   "metadata": {},
   "source": [
    "### Abby -- Please introduce:\n",
    "- syntax and concept of type hinting\n",
    "- why type hinting is helpful\n",
    "- examples as needed!\n",
    "\n",
    "Feel free to reference the solution to this week's independent assignment. I have type hinted all of the skeleton code for consistency."
   ]
  },
  {
   "cell_type": "markdown",
   "metadata": {},
   "source": [
    "## Error Messages"
   ]
  },
  {
   "cell_type": "markdown",
   "metadata": {},
   "source": [
    "When writing your own code, you will often get error messages. Below are a few examples of some of the most common errors and how to fix them.\n",
    "\n",
    "|Error Type|Occurs When...|\n",
    "|------------|-----|\n",
    "|SyntaxError|When keywords are mispelled, missing parentheses, missing apostrophes|\n",
    "|NameError|When variabe is used before being defined|\n",
    "|TypeError|When variable is used as though it is a different data type|\n",
    "|IndexError|When index asked for is larger than the length of list or array|\n",
    "|IndentationError|When missing necessary indentation|\n",
    "|FileNotFound|When file path name or name of file is mispelled|"
   ]
  },
  {
   "cell_type": "markdown",
   "metadata": {},
   "source": [
    "Syntax errors are the most common errors you'll get when you first start writing code. Luckily in most cases the compiler will tell you how to fix your code."
   ]
  },
  {
   "cell_type": "code",
   "execution_count": 23,
   "metadata": {},
   "outputs": [
    {
     "ename": "SyntaxError",
     "evalue": "expected '(' (3786893301.py, line 1)",
     "output_type": "error",
     "traceback": [
      "\u001b[1;36m  Cell \u001b[1;32mIn[23], line 1\u001b[1;36m\u001b[0m\n\u001b[1;33m    def my_function:\u001b[0m\n\u001b[1;37m                   ^\u001b[0m\n\u001b[1;31mSyntaxError\u001b[0m\u001b[1;31m:\u001b[0m expected '('\n"
     ]
    }
   ],
   "source": [
    "def my_function:\n",
    "    pass"
   ]
  },
  {
   "cell_type": "code",
   "execution_count": 24,
   "metadata": {},
   "outputs": [
    {
     "ename": "SyntaxError",
     "evalue": "unterminated string literal (detected at line 1) (2284804863.py, line 1)",
     "output_type": "error",
     "traceback": [
      "\u001b[1;36m  Cell \u001b[1;32mIn[24], line 1\u001b[1;36m\u001b[0m\n\u001b[1;33m    example_string = 'hello\u001b[0m\n\u001b[1;37m                     ^\u001b[0m\n\u001b[1;31mSyntaxError\u001b[0m\u001b[1;31m:\u001b[0m unterminated string literal (detected at line 1)\n"
     ]
    }
   ],
   "source": [
    "example_string = 'hello"
   ]
  },
  {
   "cell_type": "markdown",
   "metadata": {},
   "source": [
    "Another common error is the NameError, which occurs when a variable is used without being defined. In the example below, the second instance of `number` is lower case, and so Python treats it as a different variable."
   ]
  },
  {
   "cell_type": "code",
   "execution_count": 3,
   "metadata": {},
   "outputs": [
    {
     "ename": "NameError",
     "evalue": "name 'number' is not defined",
     "output_type": "error",
     "traceback": [
      "\u001b[1;31m---------------------------------------------------------------------------\u001b[0m",
      "\u001b[1;31mNameError\u001b[0m                                 Traceback (most recent call last)",
      "Cell \u001b[1;32mIn[3], line 2\u001b[0m\n\u001b[0;32m      1\u001b[0m Number \u001b[38;5;241m=\u001b[39m \u001b[38;5;241m4\u001b[39m\n\u001b[1;32m----> 2\u001b[0m \u001b[38;5;28mprint\u001b[39m(\u001b[43mnumber\u001b[49m \u001b[38;5;241m+\u001b[39m \u001b[38;5;241m4\u001b[39m)\n",
      "\u001b[1;31mNameError\u001b[0m: name 'number' is not defined"
     ]
    }
   ],
   "source": [
    "Number = 4\n",
    "print(number + 4)"
   ]
  },
  {
   "cell_type": "code",
   "execution_count": 4,
   "metadata": {},
   "outputs": [
    {
     "name": "stdout",
     "output_type": "stream",
     "text": [
      "8\n"
     ]
    }
   ],
   "source": [
    "Number = 4\n",
    "print(Number + 4)"
   ]
  },
  {
   "cell_type": "markdown",
   "metadata": {},
   "source": [
    "A TypeError error message is thrown when an operation is not supported for a given data type. In the below example, we attempt to add an integer to a string. String addition and integer addition are different operations, so Python throws an error."
   ]
  },
  {
   "cell_type": "code",
   "execution_count": 5,
   "metadata": {},
   "outputs": [
    {
     "ename": "TypeError",
     "evalue": "unsupported operand type(s) for +: 'int' and 'str'",
     "output_type": "error",
     "traceback": [
      "\u001b[1;31m---------------------------------------------------------------------------\u001b[0m",
      "\u001b[1;31mTypeError\u001b[0m                                 Traceback (most recent call last)",
      "Cell \u001b[1;32mIn[5], line 3\u001b[0m\n\u001b[0;32m      1\u001b[0m number_string \u001b[38;5;241m=\u001b[39m \u001b[38;5;124m'\u001b[39m\u001b[38;5;124m100\u001b[39m\u001b[38;5;124m'\u001b[39m\n\u001b[0;32m      2\u001b[0m integer \u001b[38;5;241m=\u001b[39m \u001b[38;5;241m100\u001b[39m\n\u001b[1;32m----> 3\u001b[0m \u001b[43minteger\u001b[49m\u001b[43m \u001b[49m\u001b[38;5;241;43m+\u001b[39;49m\u001b[43m \u001b[49m\u001b[43mnumber_string\u001b[49m\n",
      "\u001b[1;31mTypeError\u001b[0m: unsupported operand type(s) for +: 'int' and 'str'"
     ]
    }
   ],
   "source": [
    "number_string = '100'\n",
    "integer = 100\n",
    "integer + number_string"
   ]
  },
  {
   "cell_type": "code",
   "execution_count": 6,
   "metadata": {},
   "outputs": [
    {
     "name": "stdout",
     "output_type": "stream",
     "text": [
      "100100\n",
      "200\n"
     ]
    }
   ],
   "source": [
    "print(number_string+str(integer))\n",
    "print(int(number_string)+integer)"
   ]
  },
  {
   "cell_type": "markdown",
   "metadata": {},
   "source": [
    "Below are two examples of `IndexError`."
   ]
  },
  {
   "cell_type": "code",
   "execution_count": 7,
   "metadata": {},
   "outputs": [
    {
     "ename": "IndexError",
     "evalue": "list index out of range",
     "output_type": "error",
     "traceback": [
      "\u001b[1;31m---------------------------------------------------------------------------\u001b[0m",
      "\u001b[1;31mIndexError\u001b[0m                                Traceback (most recent call last)",
      "Cell \u001b[1;32mIn[7], line 2\u001b[0m\n\u001b[0;32m      1\u001b[0m my_list \u001b[38;5;241m=\u001b[39m []\n\u001b[1;32m----> 2\u001b[0m \u001b[43mmy_list\u001b[49m\u001b[43m[\u001b[49m\u001b[38;5;241;43m0\u001b[39;49m\u001b[43m]\u001b[49m\n",
      "\u001b[1;31mIndexError\u001b[0m: list index out of range"
     ]
    }
   ],
   "source": [
    "my_list = []\n",
    "my_list[0]"
   ]
  },
  {
   "cell_type": "code",
   "execution_count": 8,
   "metadata": {},
   "outputs": [
    {
     "ename": "IndexError",
     "evalue": "list index out of range",
     "output_type": "error",
     "traceback": [
      "\u001b[1;31m---------------------------------------------------------------------------\u001b[0m",
      "\u001b[1;31mIndexError\u001b[0m                                Traceback (most recent call last)",
      "Cell \u001b[1;32mIn[8], line 2\u001b[0m\n\u001b[0;32m      1\u001b[0m my_list \u001b[38;5;241m=\u001b[39m [\u001b[38;5;241m1\u001b[39m,\u001b[38;5;241m2\u001b[39m,\u001b[38;5;241m3\u001b[39m,\u001b[38;5;241m4\u001b[39m]\n\u001b[1;32m----> 2\u001b[0m \u001b[43mmy_list\u001b[49m\u001b[43m[\u001b[49m\u001b[38;5;241;43m4\u001b[39;49m\u001b[43m]\u001b[49m\n",
      "\u001b[1;31mIndexError\u001b[0m: list index out of range"
     ]
    }
   ],
   "source": [
    "my_list = [1,2,3,4]\n",
    "my_list[4]"
   ]
  },
  {
   "cell_type": "markdown",
   "metadata": {},
   "source": [
    "If statements and function definitions both require indentation."
   ]
  },
  {
   "cell_type": "code",
   "execution_count": 15,
   "metadata": {},
   "outputs": [
    {
     "ename": "IndentationError",
     "evalue": "expected an indented block after 'if' statement on line 1 (2728305495.py, line 2)",
     "output_type": "error",
     "traceback": [
      "\u001b[1;36m  Cell \u001b[1;32mIn[15], line 2\u001b[1;36m\u001b[0m\n\u001b[1;33m    print('Hello!')\u001b[0m\n\u001b[1;37m    ^\u001b[0m\n\u001b[1;31mIndentationError\u001b[0m\u001b[1;31m:\u001b[0m expected an indented block after 'if' statement on line 1\n"
     ]
    }
   ],
   "source": [
    "if True:\n",
    "print('Hello!')"
   ]
  },
  {
   "cell_type": "code",
   "execution_count": 16,
   "metadata": {},
   "outputs": [
    {
     "ename": "IndentationError",
     "evalue": "expected an indented block after function definition on line 1 (3252553321.py, line 2)",
     "output_type": "error",
     "traceback": [
      "\u001b[1;36m  Cell \u001b[1;32mIn[16], line 2\u001b[1;36m\u001b[0m\n\u001b[1;33m    pass\u001b[0m\n\u001b[1;37m    ^\u001b[0m\n\u001b[1;31mIndentationError\u001b[0m\u001b[1;31m:\u001b[0m expected an indented block after function definition on line 1\n"
     ]
    }
   ],
   "source": [
    "def my_function():\n",
    "pass"
   ]
  },
  {
   "cell_type": "markdown",
   "metadata": {},
   "source": [
    "Below is a `FileNotFoundError`. "
   ]
  },
  {
   "cell_type": "code",
   "execution_count": 42,
   "metadata": {},
   "outputs": [
    {
     "ename": "FileNotFoundError",
     "evalue": "[Errno 2] No such file or directory: './3_single_responsibility_principl.ipynb'",
     "output_type": "error",
     "traceback": [
      "\u001b[1;31m---------------------------------------------------------------------------\u001b[0m",
      "\u001b[1;31mFileNotFoundError\u001b[0m                         Traceback (most recent call last)",
      "Cell \u001b[1;32mIn[42], line 1\u001b[0m\n\u001b[1;32m----> 1\u001b[0m file \u001b[38;5;241m=\u001b[39m \u001b[38;5;28;43mopen\u001b[39;49m\u001b[43m(\u001b[49m\u001b[38;5;124;43m'\u001b[39;49m\u001b[38;5;124;43m./3_single_responsibility_principl.ipynb\u001b[39;49m\u001b[38;5;124;43m'\u001b[39;49m\u001b[43m)\u001b[49m\n",
      "File \u001b[1;32m~\\AppData\\Roaming\\Python\\Python312\\site-packages\\IPython\\core\\interactiveshell.py:324\u001b[0m, in \u001b[0;36m_modified_open\u001b[1;34m(file, *args, **kwargs)\u001b[0m\n\u001b[0;32m    317\u001b[0m \u001b[38;5;28;01mif\u001b[39;00m file \u001b[38;5;129;01min\u001b[39;00m {\u001b[38;5;241m0\u001b[39m, \u001b[38;5;241m1\u001b[39m, \u001b[38;5;241m2\u001b[39m}:\n\u001b[0;32m    318\u001b[0m     \u001b[38;5;28;01mraise\u001b[39;00m \u001b[38;5;167;01mValueError\u001b[39;00m(\n\u001b[0;32m    319\u001b[0m         \u001b[38;5;124mf\u001b[39m\u001b[38;5;124m\"\u001b[39m\u001b[38;5;124mIPython won\u001b[39m\u001b[38;5;124m'\u001b[39m\u001b[38;5;124mt let you open fd=\u001b[39m\u001b[38;5;132;01m{\u001b[39;00mfile\u001b[38;5;132;01m}\u001b[39;00m\u001b[38;5;124m by default \u001b[39m\u001b[38;5;124m\"\u001b[39m\n\u001b[0;32m    320\u001b[0m         \u001b[38;5;124m\"\u001b[39m\u001b[38;5;124mas it is likely to crash IPython. If you know what you are doing, \u001b[39m\u001b[38;5;124m\"\u001b[39m\n\u001b[0;32m    321\u001b[0m         \u001b[38;5;124m\"\u001b[39m\u001b[38;5;124myou can use builtins\u001b[39m\u001b[38;5;124m'\u001b[39m\u001b[38;5;124m open.\u001b[39m\u001b[38;5;124m\"\u001b[39m\n\u001b[0;32m    322\u001b[0m     )\n\u001b[1;32m--> 324\u001b[0m \u001b[38;5;28;01mreturn\u001b[39;00m \u001b[43mio_open\u001b[49m\u001b[43m(\u001b[49m\u001b[43mfile\u001b[49m\u001b[43m,\u001b[49m\u001b[43m \u001b[49m\u001b[38;5;241;43m*\u001b[39;49m\u001b[43margs\u001b[49m\u001b[43m,\u001b[49m\u001b[43m \u001b[49m\u001b[38;5;241;43m*\u001b[39;49m\u001b[38;5;241;43m*\u001b[39;49m\u001b[43mkwargs\u001b[49m\u001b[43m)\u001b[49m\n",
      "\u001b[1;31mFileNotFoundError\u001b[0m: [Errno 2] No such file or directory: './3_single_responsibility_principl.ipynb'"
     ]
    }
   ],
   "source": [
    "file = open('./3_single_responsibility_principl.ipynb')"
   ]
  },
  {
   "cell_type": "markdown",
   "metadata": {},
   "source": [
    "## Exceptions"
   ]
  },
  {
   "cell_type": "markdown",
   "metadata": {},
   "source": [
    "### Shreya -- Please talk about exceptions and how they differ from errors!"
   ]
  },
  {
   "cell_type": "markdown",
   "metadata": {},
   "source": [
    "### `try` and `except`"
   ]
  },
  {
   "cell_type": "markdown",
   "metadata": {},
   "source": [
    "### Shreya -- Please introduce the idea of `try` and `except`, specifically:\n",
    "- why we use them\n",
    "- note that they should not be used to make actually broken code \"just work\"\n",
    "\n",
    "A simple example is written below, but please add some of your own!"
   ]
  },
  {
   "cell_type": "code",
   "execution_count": 1,
   "metadata": {},
   "outputs": [
    {
     "name": "stdout",
     "output_type": "stream",
     "text": [
      "You cannot divide by zero.\n"
     ]
    }
   ],
   "source": [
    "try:\n",
    "    x = int(input(\"Enter a number: \"))\n",
    "    y = 10 / x\n",
    "    print(\"The result is:\", y)\n",
    "except ValueError:\n",
    "    print(\"You must enter a valid integer.\")\n",
    "except ZeroDivisionError:\n",
    "    print(\"You cannot divide by zero.\")"
   ]
  },
  {
   "cell_type": "markdown",
   "metadata": {},
   "source": [
    "An additional reference about errors and exceptions can be accessed [here](https://www.geeksforgeeks.org/errors-and-exceptions-in-python/)"
   ]
  }
 ],
 "metadata": {
  "kernelspec": {
   "display_name": "base",
   "language": "python",
   "name": "python3"
  },
  "language_info": {
   "codemirror_mode": {
    "name": "ipython",
    "version": 3
   },
   "file_extension": ".py",
   "mimetype": "text/x-python",
   "name": "python",
   "nbconvert_exporter": "python",
   "pygments_lexer": "ipython3",
   "version": "3.12.4"
  }
 },
 "nbformat": 4,
 "nbformat_minor": 2
}
